<?xml version="1.0"?> <!--encoding="utf-8"-->
<!-- This URDF was automatically created by SolidWorks to URDF Exporter! Originally created by Stephen Brawner (brawner@gmail.com) 
     Commit Version: 1.5.1-0-g916b5db  Build Version: 1.5.7152.31018
     For more information, please see http://wiki.ros.org/sw_urdf_exporter -->
<robot
  name="powerarm_urdf">
  <link
    name="base_link">
    <inertial>
      <origin
        xyz="0.08978 0.00062379 0.45981"
        rpy="0 0 0" />
      <mass
        value="112.73" />
      <inertia
        ixx="5.4398"
        ixy="-0.024922"
        ixz="-0.040023"
        iyy="7.5698"
        iyz="0.00089869"
        izz="6.4436" />
    </inertial>
    <visual>
      <origin
        xyz="0 0 0"
        rpy="0 0 0" />
      <geometry>
        <mesh
          filename="package://powerarm_urdf/meshes/base_link.STL" />
      </geometry>
      <material
        name="">
        <color
          rgba="0.75294 0.75294 0.75294 1" />
      </material>
    </visual>
    <collision>
      <origin
        xyz="0 0 0"
        rpy="0 0 0" />
      <geometry>
        <mesh
          filename="package://powerarm_urdf/meshes/base_link.STL" />
      </geometry>
    </collision>
  </link>
  <link
    name="shoulder_link_1">
    <inertial>
      <origin
        xyz="-0.0035312 -0.13515 -0.1295"
        rpy="0 0 0" />
      <mass
        value="7.4897" />
      <inertia
        ixx="0.044348"
        ixy="0.00014185"
        ixz="-0.0023816"
        iyy="0.042453"
        iyz="-0.0062172"
        izz="0.01437" />
    </inertial>
    <visual>
      <origin
        xyz="0 0 0"
        rpy="0 0 0" />
      <geometry>
        <mesh
          filename="package://powerarm_urdf/meshes/shoulder_link_1.STL" />
      </geometry>
      <material
        name="">
        <color
          rgba="0.75294 0.75294 0.75294 1" />
      </material>
    </visual>
    <collision>
      <origin
        xyz="0 0 0"
        rpy="0 0 0" />
      <geometry>
        <mesh
          filename="package://powerarm_urdf/meshes/shoulder_link_1.STL" />
      </geometry>
    </collision>
  </link>
  <joint
    name="shoulder_joint_1"
    type="revolute">
    <origin
      xyz="0.698849999997198 0 1.31618749999962"
      rpy="0 0 0" />
    <parent
      link="base_link" />
    <child
      link="shoulder_link_1" />
    <axis
      xyz="0 0 1" />
    <limit
      lower="-1.5708"
      upper="0.785398"
      effort="0"
      velocity="1.2" />
  </joint>
  <link
    name="shoulder_link_2">
    <inertial>
      <origin
        xyz="0.20026 6.1667E-05 0.010577"
        rpy="0 0 0" />
      <mass
        value="2.9675" />
      <inertia
        ixx="0.0050711"
        ixy="-0.00032811"
        ixz="4.6868E-05"
        iyy="0.0067807"
        iyz="-4.7618E-05"
        izz="0.0074734" />
    </inertial>
    <visual>
      <origin
        xyz="0 0 0"
        rpy="0 0 0" />
      <geometry>
        <mesh
          filename="package://powerarm_urdf/meshes/shoulder_link_2.STL" />
      </geometry>
      <material
        name="">
        <color
          rgba="0.64706 0.61961 0.58824 1" />
      </material>
    </visual>
    <collision>
      <origin
        xyz="0 0 0"
        rpy="0 0 0" />
      <geometry>
        <mesh
          filename="package://powerarm_urdf/meshes/shoulder_link_2.STL" />
      </geometry>
    </collision>
  </link>
  <joint
    name="shoulder_joint_2"
    type="revolute">
    <origin
      xyz="0 -0.14543 -0.2634"
      rpy="-1.5708 0 0" />
    <parent
      link="shoulder_link_1" />
    <child
      link="shoulder_link_2" />
    <axis
      xyz="0 0 1" />
    <limit
      lower="-0.5236"
      upper="1.5708"
      effort="0"
      velocity="1.2" />
  </joint>
  <link
    name="shoulder_link_3">
    <inertial>
      <origin
        xyz="0.0202099636303003 -0.0599945572053269 0.0704737638953157"
        rpy="0 0 0" />
      <mass
        value="2.82114385353419" />
      <inertia
        ixx="0.0132587231747916"
        ixy="-8.46028875588094E-05"
        ixz="-8.67752367351025E-05"
        iyy="0.00609813579413896"
        iyz="0.000218903832691613"
        izz="0.0114660345254401" />
    </inertial>
    <visual>
      <origin
        xyz="0 0 0"
        rpy="0 0 0" />
      <geometry>
        <mesh
          filename="package://powerarm_urdf/meshes/shoulder_link_3.STL" />
      </geometry>
      <material
        name="">
        <color
          rgba="0.752941176470588 0.752941176470588 0.752941176470588 1" />
      </material>
    </visual>
    <collision>
      <origin
        xyz="0 0 0"
        rpy="0 0 0" />
      <geometry>
        <mesh
          filename="package://powerarm_urdf/meshes/shoulder_link_3.STL" />
      </geometry>
    </collision>
  </link>
  <joint
    name="shoulder_joint_3"
    type="revolute">
    <origin
      xyz="0.19163 0.02842 0.17343"
      rpy="0 1.5708 0" />
    <parent
      link="shoulder_link_2" />
    <child
      link="shoulder_link_3" />
    <axis
      xyz="0 0 1" />
    <limit
      lower="-1.5708"
      upper="1.5708"
      effort="0"
      velocity="1.2" />
  </joint>
  <link
    name="elbow_link">
    <inertial>
      <origin
        xyz="0.0833479518409536 0.159223242917024 -0.00723299079194639"
        rpy="0 0 0" />
      <mass
        value="1.57382211837424" />
      <inertia
        ixx="0.00717308542457007"
        ixy="0.000906020103415368"
        ixz="-0.000192894255123084"
        iyy="0.00334880720547541"
        iyz="0.0003540693463422"
        izz="0.00622703611680052" />
    </inertial>
    <visual>
      <origin
        xyz="0 0 0"
        rpy="0 0 0" />
      <geometry>
        <mesh
          filename="package://powerarm_urdf/meshes/elbow_link.STL" />
      </geometry>
      <material
        name="">
        <color
          rgba="0.752941176470588 0.752941176470588 0.752941176470588 1" />
      </material>
    </visual>
    <collision>
      <origin
        xyz="0 0 0"
        rpy="0 0 0" />
      <geometry>
        <mesh
          filename="package://powerarm_urdf/meshes/elbow_link.STL" />
      </geometry>
    </collision>
  </link>
  <joint
    name="elbow_joint"
    type="revolute">
    <origin
      xyz="-0.0096516 0 0.09"
      rpy="1.5708 0 0" />
    <parent
      link="shoulder_link_3" />
    <child
      link="elbow_link" />
    <axis
      xyz="0 0 1" />
    <limit
      lower="0"
      upper="1.5708"
      effort="0"
      velocity="1.2" />
  </joint>
  <link
    name="ee_link">
    <inertial>
      <origin
        xyz="-2.6459E-08 1.0933E-07 0.0035936"
        rpy="0 0 0" />
      <mass
        value="0.027068" />
      <inertia
        ixx="9.6046E-06"
        ixy="5.0468E-11"
        ixz="-1.2285E-11"
        iyy="9.6044E-06"
        iyz="5.3157E-11"
        izz="2.0893E-06" />
    </inertial>
    <visual>
      <origin
        xyz="0 0 0"
        rpy="0 0 0" />
      <geometry>
        <mesh
          filename="package://powerarm_urdf/meshes/ee_link.STL" />
      </geometry>
      <material
        name="">
        <color
          rgba="0.75294 0.75294 0.75294 1" />
      </material>
    </visual>
    <collision>
      <origin
        xyz="0 0 0"
        rpy="0 0 0" />
      <geometry>
        <mesh
          filename="package://powerarm_urdf/meshes/ee_link.STL" />
      </geometry>
    </collision>
  </link>
  <joint
    name="ee_joint"
    type="fixed">
    <origin
      xyz="0.0105000002665487 0.344 0.000499999999998835"
      rpy="0 0 0" />
    <parent
      link="elbow_link" />
    <child
      link="ee_link" />
    <axis
      xyz="0 0 0" />
  </joint>

  <!-- Used for fixing robot to Gazebo 'base_link' -->
  <link name="world"/>

    <joint name="fixed" type="fixed">
      <parent link="world"/>
      <child link="base_link"/>
    </joint>

  <gazebo reference="base_link">
    <material>Gazebo/White</material>
    <gravity>true</gravity>
    <selfColide>false</selfColide>
  </gazebo>
  <gazebo reference="shoulder_link_1">
    <material>Gazebo/White</material>
    <gravity>true</gravity>
    <selfColide>false</selfColide>
  </gazebo>
  <gazebo reference="shoulder_link_2">
    <material>Gazebo/White</material>
    <gravity>true</gravity>
    <selfColide>false</selfColide>
  </gazebo>
  <gazebo reference="shoulder_link_3">
    <material>Gazebo/White</material>
    <gravity>true</gravity>
    <selfColide>false</selfColide>
  </gazebo>
  <gazebo reference="elbow_link">
    <material>Gazebo/White</material>
    <gravity>true</gravity>
    <selfColide>false</selfColide>
  </gazebo>
  <gazebo reference="ee_link">
    <material>Gazebo/White</material>
    <gravity>true</gravity>
    <selfColide>false</selfColide>
  </gazebo>  

  <!--comment if need-->
  <ros2_control name="GazeboSystem" type="system">
    <hardware>
        <plugin>gazebo_ros2_control/GazeboSystem</plugin>
    </hardware>
    <joint name="shoulder_joint_1">
        <command_interface name="position"/>
        <state_interface name="position">
          <param name="initial_value">0.0</param>
        </state_interface>
        <state_interface name="velocity"/>
    </joint>
    <joint name="shoulder_joint_2">
        <command_interface name="position"/>

        <state_interface name="position">
          <param name="initial_value">0.0</param>
        </state_interface>
        <state_interface name="velocity"/>
    </joint>
    <joint name="shoulder_joint_3">
        <command_interface name="position"/>

        <state_interface name="position">
          <param name="initial_value">0.0</param>
        </state_interface>
        <state_interface name="velocity"/>
    </joint>
    <joint name="elbow_joint">
        <command_interface name="position"/>

        <state_interface name="position">
          <param name="initial_value">0.0</param>
        </state_interface>
        <state_interface name="velocity"/>
    </joint>
  </ros2_control>

  <gazebo>
    <plugin name="gazebo_ros2_control" filename="libgazebo_ros2_control.so">
      <parameters>$(find powerarm_urdf)/config/ros2_controllers.yaml</parameters>
      <!-- <robot_param_node>robot_state_publisher</robot_param_node> -->
    </plugin>
  </gazebo>
</robot>